<?xml version="1.0"?>

<robot
  xmlns:sensor="http://playerstage.sourceforge.net/gazebo/xmlschema/#sensor"
  xmlns:controller="http://playerstage.sourceforge.net/gazebo/xmlschema/#controller"
  xmlns:interface="http://playerstage.sourceforge.net/gazebo/xmlschema/#interface"
  xmlns:xacro="http://ros.org/wiki/xacro">

  <!-- Properties (Constants) -->
  <property name="M_PI" value="3.14159"/>

  <!-- Right/Left Wheel -->
  <xacro:macro name="p3dx_wheel" params="suffix parent reflect">
    <link name="${suffix}_link">
      <inertial>
        <mass value="1.5"/>
        <origin rpy="${M_PI/2} 0 0"/>
        <inertia ixx="0.0051" ixy="0" ixz="0" iyy="0.0051" iyz="0" izz="0.0090"/>
      </inertial>
      <collision>
        <origin rpy="${M_PI/2} 0 0"/>
        <geometry>
          <cylinder length="0.05" radius="0.11"/>
        </geometry>
      </collision>
      <visual name="${suffix}_link_visual">
        <origin rpy="0 0 ${reflect*M_PI}"/>
        <geometry name="wheel_geom">
          <mesh filename="package://pioneer3dx_description/meshes/pioneer3dx/wheel.dae"/>
        </geometry>
      </visual>
    </link>
    <gazebo reference="${suffix}_link">
      <mu1>0.5</mu1>
      <mu2>50.0</mu2>
      <kp>100000000.0</kp>
      <kd>1.0</kd>
    </gazebo>
    <joint name="${parent}_${suffix}_link_joint" type="continuous">
      <axis xyz="0 1 0"/>
      <anchor xyz="0 0 0"/>
      <limit effort="100" velocity="100"/>
      <joint_properties damping="0.0" friction="0.0"/>
      <origin rpy="0 0 0" xyz="0.1 ${-0.34*reflect+0.17} 0.11"/>
      <parent link="${parent}"/>
      <child link="${suffix}_link"/>
    </joint>
    <transmission name="${parent}_${suffix}_link_trans">
      <type>transmission_interface/SimpleTransmission</type>
      <joint name="${parent}_${suffix}_link_joint">
        <hardwareInterface>EffortJointInterface</hardwareInterface>
      </joint>
      <actuator name="${parent}_${suffix}_link_motor">
        <hardwareInterface>EffortJointInterface</hardwareInterface>
        <mechanicalReduction>1</mechanicalReduction>
      </actuator>
    </transmission>
  </xacro:macro>
</robot>

