<?xml version="1.0" ?>
<sdf version="1.5">
  <model name="forklift">
    <pose>0 0 0 0 0 0</pose>
    <static>false</static>
    <!-- Base/Support link -->
    <link name="base_link">
      <inertial>
        <pose>0.237624 0 0.122112 0 0 0</pose>
        <mass>0.1</mass>
        <inertia>
          <ixx>0.00101506</ixx>
          <ixy>0</ixy>
          <ixz>-2.93069e-05</ixz>
          <iyy>0.00107209</iyy>
          <iyz>0</iyz>
          <izz>0.00105703</izz>
        </inertia>
      </inertial>
      <collision name="base_link_collision">
        <pose>0.24 0 0.123333 0 0 0</pose>
        <geometry>
          <box>
            <size>0.06 0.2 0.06</size>
          </box>
        </geometry>
      </collision>
      <visual name="base_link_visual">
        <pose>0.24 0 0.123333 0 0 0</pose>
        <geometry>
          <box>
            <size>0.06 0.2 0.06</size>
          </box>
        </geometry>
        <material>
          <script>
            <uri>file://media/materials/scripts/gazebo.material</uri>
            <name>Gazebo/Grey</name>
          </script>
        </material>
      </visual>
      <gravity>1</gravity>
      <velocity_decay/>
    </link>
    
    <!-- Fingers link -->
    <link name='fingers_link'>
      <pose>0.275 0 0.076667 0 0 0</pose>
      <inertial>
        <pose>0.087857 0 -0.014286 0 0 0</pose>
        <mass>0.7</mass>
        <inertia>
          <ixx>0.00957381</ixx>
          <ixy>0</ixy>
          <ixz>0.00107643</ixz>
          <iyy>0.0124168</iyy>
          <iyz>0</iyz>
          <izz>0.014163</izz>
        </inertia>
      </inertial>

      <!-- Base -->
      <collision name='fingers_base_collision'>
        <pose>0 0 0 0 0 0</pose>
        <geometry>
          <box>
            <size>0.01 0.1 0.02</size>
          </box>
        </geometry>
      </collision>
      <visual name='fingers_base_visual'>
        <pose>0 0 0 0 0 0</pose>
        <geometry>
          <box>
            <size>0.01 0.12 0.02</size>
          </box>
        </geometry>
        <material>
          <script>
            <uri>file://media/materials/scripts/gazebo.material</uri>
            <name>Gazebo/Grey</name>
          </script>
        </material>
      </visual>

      <!-- Left horizontal finger -->
      <collision name='finger_left_horizontal_collision'>
        <pose>0.105 -0.06 -0.041667 0 1.5208 0</pose>
        <geometry>
          <box>
            <size>0.01 0.02 0.2</size>
          </box>
        </geometry>
      </collision>
      <visual name='finger_left_horizontal_visual'>
        <pose>0.105 -0.06 -0.041667 0 1.5208 0</pose>
        <geometry>
          <box>
            <size>0.01 0.02 0.2</size>
          </box>
        </geometry>
        <material>
          <script>
            <uri>file://media/materials/scripts/gazebo.material</uri>
            <name>Gazebo/Grey</name>
          </script>
        </material>
      </visual>

      <!-- Left finger, horizontal end -->
      <collision name='finger_left_horizontal_end_collision'>
        <pose>0.2025 -0.06 -0.026667 0 1.5208 0</pose>
        <geometry>
          <box>
            <size>0.01 0.02 0.005</size>
          </box>
        </geometry>
      </collision>
      <visual name='finger_left_horizontal_end_visual'>
        <pose>0.2025 -0.06 -0.026667 0 1.5208 0</pose>
        <geometry>
          <box>
            <size>0.01 0.02 0.005</size>
          </box>
        </geometry>
        <material>
          <script>
            <uri>file://media/materials/scripts/gazebo.material</uri>
            <name>Gazebo/Grey</name>
          </script>
        </material>
      </visual>
      
      <!-- Right horizontal finger -->
      <collision name='finger_right_horizontal_collision'>
        <pose>0.105 0.06 -0.041667 0 1.5208 0</pose>
        <geometry>
          <box>
            <size>0.01 0.02 0.2</size>
          </box>
        </geometry>
      </collision>
      <visual name='finger_right_horizontal_visual'>
        <pose>0.105 0.06 -0.041667 0 1.5208 0</pose>
        <geometry>
          <box>
            <size>0.01 0.02 0.2</size>
          </box>
        </geometry>
        <material>
          <script>
            <uri>file://media/materials/scripts/gazebo.material</uri>
            <name>Gazebo/Grey</name>
          </script>
        </material>
      </visual>

      <!-- Right finger, horizontal end -->
      <collision name='finger_right_horizontal_end_collision'>
        <pose>0.2025 0.06 -0.026667 0 1.5208 0</pose>
        <geometry>
          <box>
            <size>0.01 0.02 0.005</size>
          </box>
        </geometry>
      </collision>
      <visual name='finger_right_horizontal_end_visual'>
        <pose>0.2025 0.06 -0.026667 0 1.5208 0</pose>
        <geometry>
          <box>
            <size>0.01 0.02 0.005</size>
          </box>
        </geometry>
        <material>
          <script>
            <uri>file://media/materials/scripts/gazebo.material</uri>
            <name>Gazebo/Grey</name>
          </script>
        </material>
      </visual>

      <!-- Left finger, vertical support -->
      <collision name='finger_left_vertical_collision'>
        <pose>0 -0.06 0.018333 0 0 0</pose>
        <geometry>
          <box>
            <size>0.01 0.02 0.14</size>
          </box>
        </geometry>
      </collision>
      <visual name='finger_left_vertical_visual'>
        <pose>0 -0.06 0.018333 0 0 0</pose>
        <geometry>
          <box>
            <size>0.01 0.02 0.14</size>
          </box>
        </geometry>
        <material>
          <script>
            <uri>file://media/materials/scripts/gazebo.material</uri>
            <name>Gazebo/Grey</name>
          </script>
        </material>
      </visual> 

      <!-- Right finger, vertical support -->
     <collision name='finger_right_vertical_collision'>
        <pose>0 0.06 0.018333 0 0 0</pose>
        <geometry>
          <box>
            <size>0.01 0.02 0.14</size>
          </box>
        </geometry>
      </collision>
      <visual name='finger_right_vertical_visual'>
        <pose>0 0.06 0.018333 0 0 0</pose>
        <geometry>
          <box>
            <size>0.01 0.02 0.14</size>
          </box>
        </geometry>
        <material>
          <script>
            <uri>file://media/materials/scripts/gazebo.material</uri>
            <name>Gazebo/Grey</name>
          </script>
        </material>
      </visual>
      <velocity_decay/>
      <gravity>1</gravity>
    </link>
   
    <!-- Prismatic joint -->
    <joint name='forklift_joint' type='prismatic'>
      <child>fingers_link</child>
      <parent>base_link</parent>
      <axis>
        <xyz>0 0 1</xyz>
        <limit>
          <lower>0</lower>
          <upper>10.08</upper>
          <effort>1000</effort>
          <velocity>0.2</velocity>
        </limit>
        <dynamics>
          <damping>10</damping>
          <friction>0</friction>
          <spring_reference>0</spring_reference>
          <spring_stiffness>0</spring_stiffness>
        </dynamics>
        <use_parent_model_frame>1</use_parent_model_frame>
      </axis>
    </joint>
  </model>
</sdf>
